[2021-05-16 04:52:29,310] {taskinstance.py:877} INFO - Dependencies all met for <TaskInstance: GAG_HW2.getCSV 2021-05-16T04:51:24.897671+00:00 [queued]>
[2021-05-16 04:52:29,370] {taskinstance.py:877} INFO - Dependencies all met for <TaskInstance: GAG_HW2.getCSV 2021-05-16T04:51:24.897671+00:00 [queued]>
[2021-05-16 04:52:29,371] {taskinstance.py:1068} INFO - 
--------------------------------------------------------------------------------
[2021-05-16 04:52:29,372] {taskinstance.py:1069} INFO - Starting attempt 1 of 2
[2021-05-16 04:52:29,373] {taskinstance.py:1070} INFO - 
--------------------------------------------------------------------------------
[2021-05-16 04:52:29,645] {taskinstance.py:1089} INFO - Executing <Task(BashOperator): getCSV> on 2021-05-16T04:51:24.897671+00:00
[2021-05-16 04:52:29,660] {standard_task_runner.py:52} INFO - Started process 52 to run task
[2021-05-16 04:52:29,669] {standard_task_runner.py:76} INFO - Running: ['airflow', 'tasks', 'run', 'GAG_HW2', 'getCSV', '2021-05-16T04:51:24.897671+00:00', '--job-id', '5', '--pool', 'default_pool', '--raw', '--subdir', 'DAGS_FOLDER/dag.py', '--cfg-path', '/tmp/tmprqycvzcs', '--error-file', '/tmp/tmpe8b0emnl']
[2021-05-16 04:52:29,674] {standard_task_runner.py:77} INFO - Job 5: Subtask getCSV
[2021-05-16 04:52:30,652] {logging_mixin.py:104} INFO - Running <TaskInstance: GAG_HW2.getCSV 2021-05-16T04:51:24.897671+00:00 [running]> on host 18c23db526a5
[2021-05-16 04:52:32,205] {taskinstance.py:1283} INFO - Exporting the following env vars:
AIRFLOW_CTX_DAG_OWNER=Shrouq_Al-Fuqahaa
AIRFLOW_CTX_DAG_ID=GAG_HW2
AIRFLOW_CTX_TASK_ID=getCSV
AIRFLOW_CTX_EXECUTION_DATE=2021-05-16T04:51:24.897671+00:00
AIRFLOW_CTX_DAG_RUN_ID=manual__2021-05-16T04:51:24.897671+00:00
[2021-05-16 04:52:32,207] {bash.py:135} INFO - Tmp dir root location: 
 /tmp
[2021-05-16 04:52:32,211] {bash.py:158} INFO - Running command: psql postgresql://postgres:postgres@de_postgres:5432 -c "\copy table1 to '/home/airflow/data/None.csv' csv header ;"
[2021-05-16 04:52:34,476] {bash.py:169} INFO - Output:
[2021-05-16 04:52:37,148] {bash.py:173} INFO - ERROR:  relation "table1" does not exist
[2021-05-16 04:52:37,153] {bash.py:177} INFO - Command exited with return code 1
[2021-05-16 04:52:37,443] {taskinstance.py:1482} ERROR - Task failed with exception
Traceback (most recent call last):
  File "/home/airflow/.local/lib/python3.6/site-packages/airflow/models/taskinstance.py", line 1138, in _run_raw_task
    self._prepare_and_execute_task_with_callbacks(context, task)
  File "/home/airflow/.local/lib/python3.6/site-packages/airflow/models/taskinstance.py", line 1311, in _prepare_and_execute_task_with_callbacks
    result = self._execute_task(context, task_copy)
  File "/home/airflow/.local/lib/python3.6/site-packages/airflow/models/taskinstance.py", line 1341, in _execute_task
    result = task_copy.execute(context=context)
  File "/home/airflow/.local/lib/python3.6/site-packages/airflow/operators/bash.py", line 180, in execute
    raise AirflowException('Bash command failed. The command returned a non-zero exit code.')
airflow.exceptions.AirflowException: Bash command failed. The command returned a non-zero exit code.
[2021-05-16 04:52:37,467] {taskinstance.py:1532} INFO - Marking task as UP_FOR_RETRY. dag_id=GAG_HW2, task_id=getCSV, execution_date=20210516T045124, start_date=20210516T045229, end_date=20210516T045237
[2021-05-16 04:52:37,951] {local_task_job.py:146} INFO - Task exited with return code 1
